2023-10-19 11:25:17,662 INFO    MainThread:546854 [wandb_setup.py:_flush():76] Current SDK version is 0.15.10
2023-10-19 11:25:17,662 INFO    MainThread:546854 [wandb_setup.py:_flush():76] Configure stats pid to 546854
2023-10-19 11:25:17,662 INFO    MainThread:546854 [wandb_setup.py:_flush():76] Loading settings from /home/Student/s4820129/.config/wandb/settings
2023-10-19 11:25:17,662 INFO    MainThread:546854 [wandb_setup.py:_flush():76] Loading settings from /home/Student/s4820129/PatternAnalysis-2023/lesion_segmentation_s4820129/wandb/settings
2023-10-19 11:25:17,662 INFO    MainThread:546854 [wandb_setup.py:_flush():76] Loading settings from environment variables: {}
2023-10-19 11:25:17,662 INFO    MainThread:546854 [wandb_setup.py:_flush():76] Applying setup settings: {'_disable_service': False}
2023-10-19 11:25:17,662 INFO    MainThread:546854 [wandb_setup.py:_flush():76] Inferring run settings from compute environment: {'program_relpath': 'train.py', 'program': '/home/Student/s4820129/PatternAnalysis-2023/lesion_segmentation_s4820129/train.py'}
2023-10-19 11:25:17,662 INFO    MainThread:546854 [wandb_init.py:_log_setup():524] Logging user logs to /home/Student/s4820129/PatternAnalysis-2023/lesion_segmentation_s4820129/wandb/run-20231019_112517-uytgmkcm/logs/debug.log
2023-10-19 11:25:17,662 INFO    MainThread:546854 [wandb_init.py:_log_setup():525] Logging internal logs to /home/Student/s4820129/PatternAnalysis-2023/lesion_segmentation_s4820129/wandb/run-20231019_112517-uytgmkcm/logs/debug-internal.log
2023-10-19 11:25:17,662 INFO    MainThread:546854 [wandb_init.py:init():564] calling init triggers
2023-10-19 11:25:17,662 INFO    MainThread:546854 [wandb_init.py:init():571] wandb.init called with sweep_config: {}
config: {}
2023-10-19 11:25:17,663 INFO    MainThread:546854 [wandb_init.py:init():614] starting backend
2023-10-19 11:25:17,663 INFO    MainThread:546854 [wandb_init.py:init():618] setting up manager
2023-10-19 11:25:17,664 INFO    MainThread:546854 [backend.py:_multiprocessing_setup():105] multiprocessing start_methods=fork,spawn,forkserver, using: spawn
2023-10-19 11:25:17,670 INFO    MainThread:546854 [wandb_init.py:init():624] backend started and connected
2023-10-19 11:25:17,671 INFO    MainThread:546854 [wandb_init.py:init():715] updated telemetry
2023-10-19 11:25:17,671 INFO    MainThread:546854 [wandb_init.py:init():748] communicating run to backend with 90.0 second timeout
2023-10-19 11:26:28,297 INFO    Thread-1 (wrapped_target):546854 [retry.py:__call__():172] Retry attempt failed:
Traceback (most recent call last):
  File "/home/Student/s4820129/miniconda3/envs/cluster_env/lib/python3.11/site-packages/urllib3/connectionpool.py", line 466, in _make_request
    six.raise_from(e, None)
  File "<string>", line 3, in raise_from
  File "/home/Student/s4820129/miniconda3/envs/cluster_env/lib/python3.11/site-packages/urllib3/connectionpool.py", line 461, in _make_request
    httplib_response = conn.getresponse()
                       ^^^^^^^^^^^^^^^^^^
  File "/home/Student/s4820129/miniconda3/envs/cluster_env/lib/python3.11/http/client.py", line 1378, in getresponse
    response.begin()
  File "/home/Student/s4820129/miniconda3/envs/cluster_env/lib/python3.11/http/client.py", line 318, in begin
    version, status, reason = self._read_status()
                              ^^^^^^^^^^^^^^^^^^^
  File "/home/Student/s4820129/miniconda3/envs/cluster_env/lib/python3.11/http/client.py", line 279, in _read_status
    line = str(self.fp.readline(_MAXLINE + 1), "iso-8859-1")
               ^^^^^^^^^^^^^^^^^^^^^^^^^^^^^^
  File "/home/Student/s4820129/miniconda3/envs/cluster_env/lib/python3.11/socket.py", line 706, in readinto
    return self._sock.recv_into(b)
           ^^^^^^^^^^^^^^^^^^^^^^^
  File "/home/Student/s4820129/miniconda3/envs/cluster_env/lib/python3.11/ssl.py", line 1278, in recv_into
    return self.read(nbytes, buffer)
           ^^^^^^^^^^^^^^^^^^^^^^^^^
  File "/home/Student/s4820129/miniconda3/envs/cluster_env/lib/python3.11/ssl.py", line 1134, in read
    return self._sslobj.read(len, buffer)
           ^^^^^^^^^^^^^^^^^^^^^^^^^^^^^^
TimeoutError: The read operation timed out

During handling of the above exception, another exception occurred:

Traceback (most recent call last):
  File "/home/Student/s4820129/miniconda3/envs/cluster_env/lib/python3.11/site-packages/requests/adapters.py", line 486, in send
    resp = conn.urlopen(
           ^^^^^^^^^^^^^
  File "/home/Student/s4820129/miniconda3/envs/cluster_env/lib/python3.11/site-packages/urllib3/connectionpool.py", line 798, in urlopen
    retries = retries.increment(
              ^^^^^^^^^^^^^^^^^^
  File "/home/Student/s4820129/miniconda3/envs/cluster_env/lib/python3.11/site-packages/urllib3/util/retry.py", line 550, in increment
    raise six.reraise(type(error), error, _stacktrace)
          ^^^^^^^^^^^^^^^^^^^^^^^^^^^^^^^^^^^^^^^^^^^^
  File "/home/Student/s4820129/miniconda3/envs/cluster_env/lib/python3.11/site-packages/urllib3/packages/six.py", line 770, in reraise
    raise value
  File "/home/Student/s4820129/miniconda3/envs/cluster_env/lib/python3.11/site-packages/urllib3/connectionpool.py", line 714, in urlopen
    httplib_response = self._make_request(
                       ^^^^^^^^^^^^^^^^^^^
  File "/home/Student/s4820129/miniconda3/envs/cluster_env/lib/python3.11/site-packages/urllib3/connectionpool.py", line 468, in _make_request
    self._raise_timeout(err=e, url=url, timeout_value=read_timeout)
  File "/home/Student/s4820129/miniconda3/envs/cluster_env/lib/python3.11/site-packages/urllib3/connectionpool.py", line 357, in _raise_timeout
    raise ReadTimeoutError(
urllib3.exceptions.ReadTimeoutError: HTTPSConnectionPool(host='api.wandb.ai', port=443): Read timed out. (read timeout=20)

During handling of the above exception, another exception occurred:

Traceback (most recent call last):
  File "/home/Student/s4820129/miniconda3/envs/cluster_env/lib/python3.11/site-packages/wandb/sdk/lib/retry.py", line 131, in __call__
    result = self._call_fn(*args, **kwargs)
             ^^^^^^^^^^^^^^^^^^^^^^^^^^^^^^
  File "/home/Student/s4820129/miniconda3/envs/cluster_env/lib/python3.11/site-packages/wandb/sdk/internal/internal_api.py", line 358, in execute
    return self.client.execute(*args, **kwargs)  # type: ignore
           ^^^^^^^^^^^^^^^^^^^^^^^^^^^^^^^^^^^^
  File "/home/Student/s4820129/miniconda3/envs/cluster_env/lib/python3.11/site-packages/wandb/vendor/gql-0.2.0/wandb_gql/client.py", line 52, in execute
    result = self._get_result(document, *args, **kwargs)
             ^^^^^^^^^^^^^^^^^^^^^^^^^^^^^^^^^^^^^^^^^^^
  File "/home/Student/s4820129/miniconda3/envs/cluster_env/lib/python3.11/site-packages/wandb/vendor/gql-0.2.0/wandb_gql/client.py", line 60, in _get_result
    return self.transport.execute(document, *args, **kwargs)
           ^^^^^^^^^^^^^^^^^^^^^^^^^^^^^^^^^^^^^^^^^^^^^^^^^
  File "/home/Student/s4820129/miniconda3/envs/cluster_env/lib/python3.11/site-packages/wandb/sdk/lib/gql_request.py", line 55, in execute
    request = self.session.post(self.url, **post_args)
              ^^^^^^^^^^^^^^^^^^^^^^^^^^^^^^^^^^^^^^^^
  File "/home/Student/s4820129/miniconda3/envs/cluster_env/lib/python3.11/site-packages/requests/sessions.py", line 637, in post
    return self.request("POST", url, data=data, json=json, **kwargs)
           ^^^^^^^^^^^^^^^^^^^^^^^^^^^^^^^^^^^^^^^^^^^^^^^^^^^^^^^^^
  File "/home/Student/s4820129/miniconda3/envs/cluster_env/lib/python3.11/site-packages/requests/sessions.py", line 589, in request
    resp = self.send(prep, **send_kwargs)
           ^^^^^^^^^^^^^^^^^^^^^^^^^^^^^^
  File "/home/Student/s4820129/miniconda3/envs/cluster_env/lib/python3.11/site-packages/requests/sessions.py", line 703, in send
    r = adapter.send(request, **kwargs)
        ^^^^^^^^^^^^^^^^^^^^^^^^^^^^^^^
  File "/home/Student/s4820129/miniconda3/envs/cluster_env/lib/python3.11/site-packages/requests/adapters.py", line 532, in send
    raise ReadTimeout(e, request=request)
requests.exceptions.ReadTimeout: HTTPSConnectionPool(host='api.wandb.ai', port=443): Read timed out. (read timeout=20)
2023-10-19 11:26:47,692 ERROR   MainThread:546854 [wandb_init.py:init():774] encountered error: Run initialization has timed out after 90.0 sec. 
Please refer to the documentation for additional information: https://docs.wandb.ai/guides/track/tracking-faq#initstarterror-error-communicating-with-wandb-process-
2023-10-19 11:26:47,823 ERROR   MainThread:546854 [wandb_init.py:init():1183] Run initialization has timed out after 90.0 sec. 
Please refer to the documentation for additional information: https://docs.wandb.ai/guides/track/tracking-faq#initstarterror-error-communicating-with-wandb-process-
Traceback (most recent call last):
  File "/home/Student/s4820129/miniconda3/envs/cluster_env/lib/python3.11/site-packages/wandb/sdk/wandb_init.py", line 1165, in init
    run = wi.init()
          ^^^^^^^^^
  File "/home/Student/s4820129/miniconda3/envs/cluster_env/lib/python3.11/site-packages/wandb/sdk/wandb_init.py", line 780, in init
    raise error
wandb.errors.CommError: Run initialization has timed out after 90.0 sec. 
Please refer to the documentation for additional information: https://docs.wandb.ai/guides/track/tracking-faq#initstarterror-error-communicating-with-wandb-process-
2023-10-19 11:26:56,096 WARNING MsgRouterThr:546854 [router.py:message_loop():77] message_loop has been closed
